<?xml version="1.0" encoding="utf-8"?>
<robot
  name="kinova">
  <link
    name="base_link">
    <inertial>
      <origin
        xyz="-0.00075876 -0.00019207 0.09605351"
        rpy="0 0 0" />
      <mass
        value="1.7565703" />
      <inertia
        ixx="0.00562309"
        ixy="5.96E-06"
        ixz="6.235E-05"
        iyy="0.00551518"
        iyz="6.09E-06"
        izz="0.00205231" />
    </inertial>
    <visual>
      <origin
        xyz="0 0 0"
        rpy="-1.57 0 0" />
      <geometry>
        <mesh
          filename="package://kortex_description/meshes/base_link.STL" />
      </geometry>
      <material
        name="">
        <color
          rgba="1 1 1 1" />
      </material>
    </visual>
    <collision>
      <origin
        xyz="0 0 0"
        rpy="0 0 0" />
      <geometry>
        <mesh
          filename="package://kortex_description/meshes/base_link.STL" />
      </geometry>
    </collision>
  </link>
  <link
    name="shoulder_link">
    <inertial>
      <origin
        xyz="-2.522E-05 -0.00759535 -0.08865077"
        rpy="0 0 0" />
      <mass
        value="1.46990145" />
      <inertia
        ixx="0.00432687"
        ixy="2.5E-07"
        ixz="9.4E-07"
        iyy="0.00447028"
        iyz="0.0001016"
        izz="0.00145324" />
    </inertial>
    <visual>
      <origin
        xyz="0 0 0"
        rpy="-1.57 0 0" />
      <geometry>
        <mesh
          filename="package://kortex_description/meshes/shoulder_link.STL" />
      </geometry>
      <material
        name="">
        <color
          rgba="0.84706 0.8549 0.85098 1" />
      </material>
    </visual>
    <collision>
      <origin
        xyz="0 0 0"
        rpy="0 0 0" />
      <geometry>
        <mesh
          filename="package://kortex_description/meshes/shoulder_link.STL" />
      </geometry>
    </collision>
  </link>
  <joint
    name="joint_1"
    type="revolute">
    <origin
      xyz="0 0 0.15643"
      rpy="3.1416 0 0" />
    <parent
      link="base_link" />
    <child
      link="shoulder_link" />
    <axis
      xyz="0 0 1" />
    <limit
      effort="39"
      velocity="1.3963" />
  </joint>
  <link
    name="half_arm_1_link">
    <inertial>
      <origin
        xyz="-4.533E-05 -0.12951716 -0.01354356"
        rpy="0 0 0" />
      <mass
        value="1.2357745" />
      <inertia
        ixx="0.0115879"
        ixy="-1.05E-06"
        ixz="5E-08"
        iyy="0.00104574"
        iyz="-0.00096902"
        izz="0.0116684" />
    </inertial>
    <visual>
      <origin
        xyz="0 0 0"
        rpy="-1.57 0 0" />
      <geometry>
        <mesh
          filename="package://kortex_description/meshes/half_arm_1_link.STL" />
      </geometry>
      <material
        name="">
        <color
          rgba="0.75294 0.75294 0.75294 1" />
      </material>
    </visual>
    <collision>
      <origin
        xyz="0 0 0"
        rpy="0 0 0" />
      <geometry>
        <mesh
          filename="package://kortex_description/meshes/half_arm_1_link.STL" />
      </geometry>
    </collision>
  </link>
  <joint
    name="joint_2"
    type="revolute">
    <origin
      xyz="0 0.005375 -0.12838"
      rpy="1.5708 0 0" />
    <parent
      link="shoulder_link" />
    <child
      link="half_arm_1_link" />
    <axis
      xyz="0 0 1" />
    <limit
      lower="-2.24"
      upper="2.24"
      effort="39"
      velocity="1.3963" />
  </joint>
  <link
    name="half_arm_2_link">
    <inertial>
      <origin
        xyz="-4.533E-05 -0.00361448 -0.14407154"
        rpy="0 0 0" />
      <mass
        value="1.2357745" />
      <inertia
        ixx="0.01009873"
        ixy="5.7E-07"
        ixz="1.89E-06"
        iyy="0.01017801"
        iyz="0.00013166"
        izz="0.00104697" />
    </inertial>
    <visual>
      <origin
        xyz="0 0 0"
        rpy="-1.57 0 0" />
      <geometry>
        <mesh
          filename="package://kortex_description/meshes/half_arm_2_link.STL" />
      </geometry>
      <material
        name="">
        <color
          rgba="0.75294 0.75294 0.75294 1" />
      </material>
    </visual>
    <collision>
      <origin
        xyz="0 0 0"
        rpy="0 0 0" />
      <geometry>
        <mesh
          filename="package://kortex_description/meshes/half_arm_2_link.STL" />
      </geometry>
    </collision>
  </link>
  <joint
    name="joint_3"
    type="revolute">
    <origin
      xyz="0 -0.21038 -0.006375"
      rpy="-1.5708 0 0" />
    <parent
      link="half_arm_1_link" />
    <child
      link="half_arm_2_link" />
    <axis
      xyz="0 0 1" />
    <limit
      effort="39"
      velocity="1.3963" />
  </joint>
  <link
    name="forearm_link">
    <inertial>
      <origin
        xyz="-0.00030188 -0.104938 -0.01559665"
        rpy="0 0 0" />
      <mass
        value="0.89954802" />
      <inertia
        ixx="0.00889854"
        ixy="1.98E-05"
        ixz="-2.39E-06"
        iyy="0.00060297"
        iyz="-0.00074456"
        izz="0.00898975" />
    </inertial>
    <visual>
      <origin
        xyz="0 0 0"
        rpy="-1.57 0 0" />
      <geometry>
        <mesh
          filename="package://kortex_description/meshes/forearm_link.STL" />
      </geometry>
      <material
        name="">
        <color
          rgba="0.84706 0.8549 0.85098 1" />
      </material>
    </visual>
    <collision>
      <origin
        xyz="0 0 0"
        rpy="0 0 0" />
      <geometry>
        <mesh
          filename="package://kortex_description/meshes/forearm_link.STL" />
      </geometry>
    </collision>
  </link>
  <joint
    name="joint_4"
    type="revolute">
    <origin
      xyz="0 0.006375 -0.210375"
      rpy="1.5708 0 0" />
    <parent
      link="half_arm_2_link" />
    <child
      link="forearm_link" />
    <axis
      xyz="0 0 1" />
    <limit
      lower="-2.57"
      upper="2.57"
      effort="39"
      velocity="1.3963" />
  </joint>
  <link
    name="spherical_wrist_1_link">
    <inertial>
      <origin
        xyz="-0.00035363 -0.00659443 -0.07560343"
        rpy="0 0 0" />
      <mass
        value="0.70588351" />
      <inertia
        ixx="0.00145671"
        ixy="3.35E-06"
        ixz="7.62E-06"
        iyy="0.00145189"
        iyz="0.00012055"
        izz="0.00039299" />
    </inertial>
    <visual>
      <origin
        xyz="0 0 0"
        rpy="-1.57 0 0" />
      <geometry>
        <mesh
          filename="package://kortex_description/meshes/spherical_wrist_1_link.STL" />
      </geometry>
      <material
        name="">
        <color
          rgba="0.84706 0.8549 0.85098 1" />
      </material>
    </visual>
    <collision>
      <origin
        xyz="0 0 0"
        rpy="0 0 0" />
      <geometry>
        <mesh
          filename="package://kortex_description/meshes/spherical_wrist_1_link.STL" />
      </geometry>
    </collision>
  </link>
  <joint
    name="joint_5"
    type="revolute">
    <origin
      xyz="0 -0.208425 -0.006375"
      rpy="-1.5708 0 0" />
    <parent
      link="forearm_link" />
    <child
      link="spherical_wrist_1_link" />
    <axis
      xyz="0 0 1" />
    <limit
      effort="9"
      velocity="1.2218" />
  </joint>
  <link
    name="spherical_wrist_2_link">
    <inertial>
      <origin
        xyz="-0.00035547 -0.06159424 -0.00850171"
        rpy="0 0 0" />
      <mass
        value="0.70583924" />
      <inertia
        ixx="0.00187208"
        ixy="6.1E-06"
        ixz="-2.17E-06"
        iyy="0.00041077"
        iyz="-0.00033774"
        izz="0.0018494" />
    </inertial>
    <visual>
      <origin
        xyz="0 0 0"
        rpy="-1.57 0 0" />
      <geometry>
        <mesh
          filename="package://kortex_description/meshes/spherical_wrist_2_link.STL" />
      </geometry>
      <material
        name="">
        <color
          rgba="0.84706 0.8549 0.85098 1" />
      </material>
    </visual>
    <collision>
      <origin
        xyz="0 0 0"
        rpy="0 0 0" />
      <geometry>
        <mesh
          filename="package://kortex_description/meshes/spherical_wrist_2_link.STL" />
      </geometry>
    </collision>
  </link>
  <joint
    name="joint_6"
    type="revolute">
    <origin
      xyz="0 0.00017505 -0.10592505"
      rpy="1.5708 0 0" />
    <parent
      link="spherical_wrist_1_link" />
    <child
      link="spherical_wrist_2_link" />
    <axis
      xyz="0 0 1" />
    <limit
      lower="-2.09"
      upper="2.09"
      effort="9"
      velocity="1.2218" />
  </joint>
  <link
    name="bracelet_link">
    <inertial>
      <origin
        xyz="-0.00027419 -0.01170136 -0.03437502"
        rpy="0 0 0" />
      <mass
        value="0.43504643" />
      <inertia
        ixx="0.00048886"
        ixy="2.59E-06"
        ixz="1.75E-06"
        iyy="0.00029425"
        iyz="8.248E-05"
        izz="0.000542" />
    </inertial>
    <visual>
      <origin
        xyz="0 0 0"
        rpy="-1.57 0 0" />
      <geometry>
        <mesh
          filename="package://kortex_description/meshes/bracelet_with_vision_link.STL" />
      </geometry>
      <material
        name="">
        <color
          rgba="0.75294 0.75294 0.75294 1" />
      </material>
    </visual>
    <collision>
      <origin
        xyz="0 0 0"
        rpy="0 0 0" />
      <geometry>
        <mesh
          filename="package://kortex_description/meshes/bracelet_with_vision_link.STL" />
      </geometry>
    </collision>
  </link>
  <joint
    name="joint_7"
    type="revolute">
    <origin
      xyz="0 -0.10592505 -0.00017505"
      rpy="-1.5708 0 0" />
    <parent
      link="spherical_wrist_2_link" />
    <child
      link="bracelet_link" />
    <axis
      xyz="0 0 1" />
    <limit
      effort="9"
      velocity="1.2218" />
  </joint>
  <link
    name="end_effector_link">
    <inertial>
      <origin
        xyz="0 0 0"
        rpy="0 0 0" />
      <mass
        value="0" />
      <inertia
        ixx="0"
        ixy="0"
        ixz="0"
        iyy="0"
        iyz="0"
        izz="0" />
    </inertial>
  </link>
  <joint
    name="end_effector"
    type="fixed">
    <origin
      xyz="0 0 -0.061525"
      rpy="-3.1415 0 1.57" />
    <parent
      link="bracelet_link" />
    <child
      link="end_effector_link" />
    <axis
      xyz="0 0 0" />
  </joint>

    <material name="Blanc">
    <color rgba="1.0 1.0 1.0 1.0"/>
  </material>
  <!-- <link name="end_effector_link">
    <origin xyz="0 0 0"/>
    <inertial>
      <mass value="0.001"/>
      <origin rpy="0 0 0" xyz="0 0 0"/>
      <inertia ixx="0" ixy="0.0" ixz="0.0" iyy="0.0" iyz="0.0" izz="0.0"/>
    </inertial>
  </link> -->
  <!-- base -->
  <joint name="base_link_robotiq_2f_85_base_joint" type="fixed">
    <origin rpy="0 0 0" xyz="0 0 0"/>
    <parent link="end_effector_link"/>
    <child link="robotiq_2f_85_base"/>
  </joint>
  <link name="robotiq_2f_85_base">
    <inertial>
      <mass value="0.1"/>
      <origin xyz="0 0 0.055"/>
      <inertia ixx="0.000190833333333" ixy="0" ixz="0" iyy="0.00018" iyz="0" izz="0.000190833333333"/>
    </inertial>
    <visual>
      <origin
        xyz="0 0 0"
        rpy="-1.57 0 0" />
      <geometry>
        <mesh filename="package://kortex_description/meshes/robotiq-2f-base.stl" scale="0.001 0.001 0.001"/>
      </geometry>
      <material name="Blanc"/>
    </visual>
    <collision>
      <geometry>
        <mesh filename="package://kortex_description/meshes/robotiq-2f-base.stl" scale="0.001 0.001 0.001"/>
      </geometry>
    </collision>
  </link>
  <!-- right finger -->
  <joint name="robotiq_2f_85_right_driver_joint" type="fixed">
    <origin rpy="0 0 0" xyz="0 0.0306011 0.054904"/>
    <parent link="robotiq_2f_85_base"/>
    <child link="robotiq_2f_85_right_driver"/>
    <axis xyz="1 0 0"/>
    <limit effort="60" lower="0.0" upper="0.834" velocity="1.91986177778"/>
  </joint>
  <link name="robotiq_2f_85_right_driver">
    <inertial>
      <mass value="0.1"/>
      <origin xyz="0 0 0.055"/>
      <inertia ixx="0.000190833333333" ixy="0" ixz="0" iyy="0.00018" iyz="0" izz="0.000190833333333"/>
    </inertial>
    <visual>
      <origin
        xyz="0 0 0"
        rpy="-1.57 0 0" />
      <geometry>
        <mesh filename="package://kortex_description/meshes/robotiq-2f-driver.stl" scale="0.001 0.001 0.001"/>
      </geometry>
      <material name="Blanc"/>
    </visual>
    <collision>
      <geometry>
        <mesh filename="package://kortex_description/meshes/robotiq-2f-driver.stl" scale="0.001 0.001 0.001"/>
      </geometry>
    </collision>
  </link>
  <joint name="robotiq_2f_85_right_coupler_joint" type="fixed">
    <origin rpy="0 0 0" xyz="0 0.0315 -0.0041"/>
    <parent link="robotiq_2f_85_right_driver"/>
    <child link="robotiq_2f_85_right_coupler"/>
  </joint>
  <link name="robotiq_2f_85_right_coupler">
    <inertial>
      <mass value="0.1"/>
      <origin xyz="0 0 0.055"/>
      <inertia ixx="0.000190833333333" ixy="0" ixz="0" iyy="0.00018" iyz="0" izz="0.000190833333333"/>
    </inertial>
    <visual>
      <origin
        xyz="0 0 0"
        rpy="-1.57 0 0" />
      <geometry>
        <mesh filename="package://kortex_description/meshes/robotiq-2f-coupler.stl" scale="0.001 0.001 0.001"/>
      </geometry>
      <material name="Blanc"/>
    </visual>
    <collision>
      <geometry>
        <mesh filename="package://kortex_description/meshes/robotiq-2f-coupler.stl" scale="0.001 0.001 0.001"/>
      </geometry>
    </collision>
  </link>
  <joint name="robotiq_2f_85_right_follower_joint" type="fixed">
    <origin rpy="0 0 0" xyz="0 0.0061 0.0471"/>
    <parent link="robotiq_2f_85_right_coupler"/>
    <child link="robotiq_2f_85_right_follower"/>
    <axis xyz="1 0 0"/>
    <limit effort="176" lower="-2.96705911111" upper="2.96705911111" velocity="1.91986177778"/>
    <mimic joint="robotiq_2f_85_right_driver_joint" multiplier="-1"/>
  </joint>
  <link name="robotiq_2f_85_right_follower">
    <visual>
      <origin
        xyz="0 0 0"
        rpy="-1.57 0 0" />
      <geometry>
        <mesh filename="package://kortex_description/meshes/robotiq-2f-follower.stl" scale="0.001 0.001 0.001"/>
      </geometry>
      <material name="Blanc"/>
    </visual>
    <collision>
      <geometry>
        <mesh filename="package://kortex_description/meshes/robotiq-2f-follower.stl" scale="0.001 0.001 0.001"/>
      </geometry>
    </collision>
    <inertial>
      <mass value="0.1"/>
      <origin xyz="0 0 0.055"/>
      <inertia ixx="0.000190833333333" ixy="0" ixz="0" iyy="0.00018" iyz="0" izz="0.000190833333333"/>
    </inertial>
  </link>
  <joint name="robotiq_2f_85_right_pad_joint" type="revolute">
			<parent link="robotiq_2f_85_right_follower"/>
			<child link="robotiq_2f_85_right_pad"/>
	</joint>
	<link name="robotiq_2f_85_right_pad">
		<inertial>
			<mass value="0.1"/>
			<origin xyz="0 0 0.055"  />
      <inertia ixx="0.00019" iyy="0.00018" izz="0.00019" ixy="0" iyz="0" ixz="0"/>
		</inertial>
		<visual>
      <origin
        xyz="0 0 0"
        rpy="-1.57 0 0" />
			<geometry>
				<mesh filename="package://kortex_description/meshes/robotiq-2f-pad.stl" scale="0.0001 0.0001 0.0001"/>
			</geometry>
      <material name="Blanc"/>
		</visual>
		<collision>
			<geometry>
				<mesh filename="package://kortex_description/meshes/robotiq-2f-pad.stl" scale="0.001 0.001 0.001"/>
			</geometry>
		</collision>
	</link>
  <joint name="robotiq_2f_85_right_spring_link_joint" type="fixed">
    <origin rpy="0 0 0" xyz="0 0.012 0.0614"/>
    <parent link="robotiq_2f_85_base"/>
    <child link="robotiq_2f_85_right_spring_link"/>
    <axis xyz="1 0 0"/>
    <limit effort="176" lower="-2.96705911111" upper="2.96705911111" velocity="1.91986177778"/>
    <mimic joint="robotiq_2f_85_right_driver_joint" multiplier="1"/>
  </joint>
  <link name="robotiq_2f_85_right_spring_link">
    <inertial>
      <mass value="0.1"/>
      <origin xyz="0 0 0.055"/>
      <inertia ixx="0.000190833333333" ixy="0" ixz="0" iyy="0.00018" iyz="0" izz="0.000190833333333"/>
    </inertial>
    <visual>
      <origin
        xyz="0 0 0"
        rpy="-1.57 0 0" />
      <geometry>
        <mesh filename="package://kortex_description/meshes/robotiq-2f-spring_link.stl" scale="0.001 0.001 0.001"/>
      </geometry>
      <material name="Blanc"/>
    </visual>
    <collision>
      <geometry>
        <mesh filename="package://kortex_description/meshes/robotiq-2f-spring_link.stl" scale="0.001 0.001 0.001"/>
      </geometry>
    </collision>
  </link>
  <!-- left finger -->
  <joint name="robotiq_2f_85_left_driver_joint" type="fixed">
    <origin rpy="0 0 3.141592653589793" xyz="0 -0.0306011 0.054904"/>
    <parent link="robotiq_2f_85_base"/>
    <child link="robotiq_2f_85_left_driver"/>
    <axis xyz="1 0 0"/>
    <limit effort="176" lower="0.0" upper="0.834" velocity="1.91986177778"/>
    <mimic joint="robotiq_2f_85_right_driver_joint" multiplier="1"/>
  </joint>
  <link name="robotiq_2f_85_left_driver">
    <inertial>
      <mass value="0.1"/>
      <origin xyz="0 0 0.055"/>
      <inertia ixx="0.000190833333333" ixy="0" ixz="0" iyy="0.00018" iyz="0" izz="0.000190833333333"/>
    </inertial>
    <visual>
      <origin
        xyz="0 0 0"
        rpy="-1.57 0 0" />
      <geometry>
        <mesh filename="package://kortex_description/meshes/robotiq-2f-driver.stl" scale="0.001 0.001 0.001"/>
      </geometry>
      <material name="Blanc"/>
    </visual>
    <collision>
      <geometry>
        <mesh filename="package://kortex_description/meshes/robotiq-2f-driver.stl" scale="0.001 0.001 0.001"/>
      </geometry>
    </collision>
  </link>
  <joint name="robotiq_2f_85_left_coupler_joint" type="fixed">
    <origin rpy="0 0 0" xyz="0 0.0315 -0.0041"/>
    <parent link="robotiq_2f_85_left_driver"/>
    <child link="robotiq_2f_85_left_coupler"/>
  </joint>
  <link name="robotiq_2f_85_left_coupler">
    <inertial>
      <mass value="0.1"/>
      <origin xyz="0 0 0.055"/>
      <inertia ixx="0.000190833333333" ixy="0" ixz="0" iyy="0.00018" iyz="0" izz="0.000190833333333"/>
    </inertial>
    <visual>
      <origin
        xyz="0 0 0"
        rpy="-1.57 0 0" />
      <geometry>
        <mesh filename="package://kortex_description/meshes/robotiq-2f-coupler.stl" scale="0.001 0.001 0.001"/>
      </geometry>
      <material name="Blanc"/>
    </visual>
    <collision>
      <geometry>
        <mesh filename="package://kortex_description/meshes/robotiq-2f-coupler.stl" scale="0.001 0.001 0.001"/>
      </geometry>
    </collision>
  </link>
  <joint name="robotiq_2f_85_left_follower_joint" type="fixed">
    <origin rpy="0 0 0" xyz="0 0.0061 0.0471"/>
    <parent link="robotiq_2f_85_left_coupler"/>
    <child link="robotiq_2f_85_left_follower"/>
    <axis xyz="1 0 0"/>
    <limit effort="176" lower="-2.96705911111" upper="2.96705911111" velocity="1.91986177778"/>
    <mimic joint="robotiq_2f_85_right_driver_joint" multiplier="-1"/>
  </joint>
  <link name="robotiq_2f_85_left_follower">
    <visual>
      <origin
        xyz="0 0 0"
        rpy="-1.57 0 0" />
      <geometry>
        <mesh filename="package://kortex_description/meshes/robotiq-2f-follower.stl" scale="0.001 0.001 0.001"/>
      </geometry>
      <material name="Blanc"/>
    </visual>
    <collision>
      <geometry>
        <mesh filename="package://kortex_description/meshes/robotiq-2f-follower.stl" scale="0.001 0.001 0.001"/>
      </geometry>
    </collision>
    <inertial>
      <mass value="0.1"/>
      <origin xyz="0 0 0.055"/>
      <inertia ixx="0.000190833333333" ixy="0" ixz="0" iyy="0.00018" iyz="0" izz="0.000190833333333"/>
    </inertial>
  </link>
  <joint name="robotiq_2f_85_left_pad_joint" type="revolute">
			<parent link="robotiq_2f_85_left_follower"/>
			<child link="robotiq_2f_85_left_pad"/>
		</joint>
		<link name="robotiq_2f_85_left_pad">
			<inertial>
				<mass value="0.1"/>
				<origin xyz="0 0 0.055"  />
				<inertia ixx="0.00019" iyy="0.00018" izz="0.00019" ixy="0" iyz="0" ixz="0"/>
			</inertial>
      <visual>
        <origin
        xyz="0 0 0"
        rpy="-1.57 0 0" />
        <geometry>
          <mesh name="a" filename="package://kortex_description/meshes/robotiq-2f-pad.stl" scale="0.0001 0.0001 0.0001"/>
        </geometry>
        <material name="Blanc"/>
      </visual>
			<collision>
				<geometry>
					<mesh name="b" filename="package://kortex_description/meshes/robotiq-2f-pad.stl" scale="0.001 0.001 0.001"/>
				</geometry>
			</collision>
		</link>
  <joint name="robotiq_2f_85_left_spring_link_joint" type="fixed">
    <origin rpy="0 0 3.141592653589793" xyz="0 -0.012 0.0614"/>
    <parent link="robotiq_2f_85_base"/>
    <child link="robotiq_2f_85_left_spring_link"/>
    <axis xyz="1 0 0"/>
    <limit effort="176" lower="-2.96705911111" upper="2.96705911111" velocity="1.91986177778"/>
    <mimic joint="robotiq_2f_85_right_driver_joint" multiplier="1"/>
  </joint>
  <link name="robotiq_2f_85_left_spring_link">
    <inertial>
      <mass value="0.1"/>
      <origin xyz="0 0 0.055"/>
      <inertia ixx="0.000190833333333" ixy="0" ixz="0" iyy="0.00018" iyz="0" izz="0.000190833333333"/>
    </inertial>
    <visual>
      <origin
        xyz="0 0 0"
        rpy="-1.57 0 0" />
      <geometry>
        <mesh filename="package://kortex_description/meshes/robotiq-2f-spring_link.stl" scale="0.001 0.001 0.001"/>
      </geometry>
      <material name="Blanc"/>
    </visual>
    <collision>
      <geometry>
        <mesh filename="package://kortex_description/meshes/robotiq-2f-spring_link.stl" scale="0.001 0.001 0.001"/>
      </geometry>
    </collision>
  </link>
  <transmission name="robotiq_2f_85_right_driver_trans">
    <type>transmission_interface/SimpleTransmission</type>
    <joint name="robotiq_2f_85_right_driver_joint">
      <hardwareInterface>hardware_interface/PositionJointInterface</hardwareInterface>
    </joint>
    <actuator name="robotiq_2f_85_right_driver_motor">
      <mechanicalReduction>1</mechanicalReduction>
    </actuator>
  </transmission>

<!--   
  <link
    name="camera_link" />
  <joint
    name="camera_module"
    type="fixed">
    <origin
      xyz="0 0.05639 -0.00305"
      rpy="3.14159265358979 3.14159265358979 0" />
    <parent
      link="end_effector_link" />
    <child
      link="camera_link" />
  </joint>
  <link
    name="camera_depth_frame" />
  <joint
    name="depth_module"
    type="fixed">
    <origin
      xyz="0.0275 0.066 -0.00305"
      rpy="3.14159265358979 3.14159265358979 0" />
    <parent
      link="end_effector_link" />
    <child
      link="camera_depth_frame" />
  </joint>
  <link
    name="camera_color_frame" />
  <joint
    name="color_module"
    type="fixed">
    <origin
      xyz="0 0.05639 -0.00305"
      rpy="3.14159265358979 3.14159265358979 0" />
    <parent
      link="end_effector_link" />
    <child
      link="camera_color_frame" />
  </joint> -->
</robot>